Workbook

Sheet DRM Diagnostic
B2: DRM System - Diagnostic
B4: Instructions
B5: 1. Answer the questions in the following matrix.
B6: 2. Go to the following website. The website may take some time to load. Please retry if needed. | E6: https://cat-ddo-drm-diagnostic-dashboard.onrender.com
B7: 3. Copy and Paste Cell E7 to the website | E7: =_xlfn.TEXTJOIN(";",FALSE,'Summary (to be hidden)'!I2:I14) -> DRM Pillar,Thematic Area,Legal and institutional set up,Intermediary DRM outputs,Key DRM achievements,Policy enablers;Legal and Institutional DRM Framework,DRM policies and institutions,0,0,0,0;Legal and Institutional DRM Framework,Mainstreaming DRM into national and sectoral development plans,0,0,0,0;Risk Identification,Risk identification,0,0,0,0;Risk Reduction,Territorial and urban planning,0,0,0,0.5;Risk Reduction,Public investment at the central level,0,0,0,0;Risk Reduction,Sector-specific risk reduction measures,0,0,0,0;Preparedness,Early warning systems,0,0,0,0;Preparedness,Emergency preparedness and response,0,0,0,0;Preparedness,Adaptive social protection,0,0,0,0;Financial Protection,Fiscal risk management,0,0,0,0;Financial Protection,DRF strategies and instruments,0,0,0,0;Resilient Reconstruction,Resilient reconstruction,0,0,0,0
B9: Number of questions unanswered: | E9: =64-(COUNTIF('DRM Diagnostic'!D12:K50,"YES")+COUNTIF('DRM Diagnostic'!D12:K50,"NO")) -> 50
B10: * Essential government entities refer to the main ministry or agency in charge of the followings sectors: Agriculture, Education, Housing, Health, Energy, Tourism, Transport, Water and Sanitation.
B12: DRM Pillar | C12: Thematic Area | D12: Question 1 | F12: Question 2 | H12: Question 3 | J12: Question 4
B13: 1. Legal and Institutional DRM Framework | C13: 1.1. DRM policies and institutions | D13: Is there a legal framework (e.g., a DRM law or other legally-binding instruments) defining distinct responsibilities for disaster risk reduction and emergency management? | F13: Did the institution responsible for coordinating or leading DRM activities receive dedicated funding for these functions in the last fiscal year? | H13: Since the adoption of the DRM legal framework: (1) have DRM policy instruments (e.g., DRM strategies or policies) been officially approved? (2) have DRM-related regulations (e.g., rules on the structure or functions of the DRM agency) been officially approved? | J13: (1) Are gender-specific considerations included in DRM legal frameworks? (2) Is climate change and its potential impact on disaster risk included in DRM legal frameworks? (3) When they exist, do climate change laws and regulations (such as climate laws or climate adaptation policy/strategies) contain disaster risk management as a target, aim, means, or result?
D14: Yes/No: | F14: Yes/No: | H14: (1) Yes/No: | J14: (1) Yes/No:
J15: (2) Yes/No: | K15: No
H16: (2) Yes/No: | J16: (3) Yes/No: | K16: No
C18: 1.2. Mainstreaming DRM into national and sectoral development plans | D18: Does the National Development Strategy (or equivalent national planning instrument) contain objectives, targets or indicators related to DRM and/or CCA? | F18: Is there a reporting or monitoring mechanism to track progress toward DRM and/or CCA targets included in the National Development Strategies? | H18: Have at least 50% of essential government entities* included explicit DRM and/or CCA targets and indicators in their most recent strategic planning documents? | J18: Is the integration of DRM considerations into sectoral planning documents coordinated at the central level and supported/guided by norms, tools and clear standards?
D19: Yes/No: | F19: Yes/No: | G19: No | H19: Yes/No: | J19: Yes/No:
B20: 2. Risk Identification | C20: - | D20: Do laws and regulations clearly define institutional responsibilities and mandates for producing, acquiring, and managing geospatial information, including risk information (e.g., hazard information, vulnerability assessments, risk profiles, historical disaster databases)? | F20: Is existing hazard and risk information: (1) available to all essential government entities (e.g., as evidenced through a set of MoUs or formal exchange mechanisms)? (2) accessible to all citizens through open-data platforms? | H20: Do at least half of the essential government entities use existing risk information to inform their sectoral planning processes? | J20: Do available national risk assessments or disaster risk profiles account for the potential impacts of climate change?
D21: Yes/No: | F21: (1) Yes/No: | H21: Yes/No: | I21: No | J21: Yes/No:
F22: (2) Yes/No:
B23: 3. Risk Reduction | C23: 3.1. Territorial and urban planning | D23: Do laws and regulations mandate the use of risk information (e.g., hazard maps, risk assessments...) to develop territorial, spatial, land use, or urban planning instruments? | F23: Do official methodologies to guide the development of risk-informed territorial, spatial, land use or urban planning instruments exist? | H23: Have at least 50% of the instruments (territorial, spatial, land use or urban planning) approved in the last 4 years used risk information (e.g., hazard maps, risk assessments)? | J23: (1) Are there specific regulations governing the identification and zoning process of high-risk areas? (2) Do guidelines or procedures for managing housing/ settlments located in high-risk areas exist?
D24: Yes/No: | F24: Yes/No: | H24: Yes/No: | J24: (1) Yes/No: | K24: Yes
J25: (2) Yes/No:
C26: 3.2. Public investment at the central level | D26: Do laws and regulations mandate disaster and climate risk screening as part of the appraisal of new public investment projects? | F26: Do official guidelines exist defining disaster and climate risk screening methodologies for new public investment projects? | H26: Are risk mitigation measures in place for new projects that have been appraised as high-risk (or equivalent) through the disaster and climate screening process? | J26: (1) Do the regulations governing environmental impact assessments (or equivalent process) include specific provisions for disaster risk analysis? (2) Are Public-Private Partnership projects also included in climate and disaster risk screening?
D27: Yes/No: | F27: Yes/No: | H27: Yes/No: | I27: No | J27: (1) Yes/No: | K27: No
J28: (2) Yes/No: | K28: No
C29: 3.3. Sector-specific risk reduction measures | D29: Are there legally binding standards or technical guidelines for the design and construction of disaster-resilient critical infrastructure in the following sectors: (1) transport (roads) (2) education (schools) (3) health (hospitals) (4) energy infrastructure? | F29: Is there at least one legally binding building code or standard that requires earthquake-resistant or other hazard-resistant (e.g., wind, flood) design for buildings? | H29: Over the last 4 years, is there at least one public project/program that has received a budget allocation for retrofitting works based on vulnerability assessments and resilient standards? | J29: Is there an asset management system for public infrastructure that includes disaster risk analysis?
D30: (1) Yes/No: | F30: Yes/No: | H30: Yes/No: | J30: Yes/No:
D31: (2) Yes/No:
D32: (3) Yes/No:
D33: (4) Yes/No:
D34: Are there legal and institutional arrangements for water supply and sanitation in urban areas that take flood risk into account? | F34: Are there legal and institutional arrangements for integrated water resources management (IWRM) that explicitly incorporate flood and drought risk considerations? | H34: Over the last 4 years: (1) have any watershed basins undergone improvements in water management? (2) has the percentage of urban residents with access to sewage services been maintained or increased? | J34: Are water governance policy documents considering changes to rainfall patterns under different climate scenarios?
D35: Yes/No: | F35: Yes/No: | H35: (1) Yes/No: | J35: Yes/No:
H36: (2) Yes/No:
B37: 4. Preparedness | C37: 4.1. Early Warning Systems (EWS) | D37: Is there a legal framework defining the roles and responsibility of institutions involved in Early Warning Systems —hazard data producers, decision-makers, and implementers of preparedness and response— and establishing functional coordination mechanism, evidenced by formal arrangements such as MoUs or regular coordination platform meetings? | F37: Do institutions involved in EWS—data producers, decision-makers, and implementers of preparedness and response—operate under an established, functional coordination mechanism, evidenced by formal arrangements such as MoUs or regular coordination platform meetings? | H37: Over the most recent major disaster, was the population promptly alerted (e.g., via SMS or other tailored communication channels)? | J37: Over the past four years, has there been at least one budget allocation for the expansion, maintenance, or operation of the hydrometeorological network?
D38: Yes/No: | F38: Yes/No: | G38: No | H38: Yes/No: | J38: Yes/No:
C39: 4.2. Emergency Preparedness and Response (EP&R) | D39: Is there a legal framework for EP&R clearly defining the roles and responsibilities of institutions involved in disaster management? | F39: Have at least 75% of the subnational EP&R entities mandated by EP&R law and regulations (or equivalent) been officially established? | H39: (1) Do at least 75% of essential government entities have an emergency response protocol or operational continuity plan? (2) Do at least 75% of existing subnational EP&R entities (e.g. Local Emergency Management Committee) have an approved contingency plan or emergency response protocol? | J39: Do emergency preparedness plans incorporate gender-sensitive measures, such as gender-based violence prevention, safe shelters, and women's specific needs during evacuation and displacement?
D40: Yes/No: | F40: Yes/No: | G40: No | H40: (1) Yes/No: | J40: Yes/No: | K40: No
H41: (2) Yes/No:
C42: 4.3. Adaptive Social Protection (ASP) | D42: Is there a legal framework clearly defining the roles and responsibilities of institutions involved in ASP (e.g., social protection, finance, DRM)? | F42: Is there a unified social registry incorporating exposure and vulnerability data to facilitate the targeting of population potentially affected in case of disaster or climate-related shocks? | H42: During the most recent disaster or climate-related shock, was support promptly provided to the population through social‐protection programs? (e.g., cash transfers in the case of flood/drought)? | J42: Are there pre-arranged financing mechanisms that can be specifically used to support timely scaling-up of regular SP programs?
D43: Yes/No: | F43: Yes/No: | H43: Yes/No: | J43: Yes/No: | K43: No
B44: 5. Financial Protection | C44: 5.1. Fiscal risk management | D44: Has the Ministry of Finance created or tasked an existing institutional structure (e.g., department, unit, committee) to manage contingent liabilities and/or fiscal risks, explicitly including those associated with disasters and/or climate-related shocks? | F44: Are contingent liabilities associated with disasters quantified through an established methodology for the major hazards? | H44: Do key fiscal policy documents (e.g., the medium-term fiscal framework or fiscal risk statements) include quantified assessments of disaster risks? | J44: Has the government conducted stress tests of public debt that include disaster or climate-related scenarios?
D45: Yes/No: | F45: Yes/No: | H45: Yes/No: | J45: Yes/No:
...

Sheet Summary (to be hidden)
B2: DRM Pillar | C2: Thematic Area | D2: Legal and institutional set up | E2: Intermediary DRM outputs | F2: Key DRM achievements | G2: Policy enablers | I2: =_xlfn.TEXTJOIN(",",FALSE,B2:G2) -> DRM Pillar,Thematic Area,Legal and institutional set up,Intermediary DRM outputs,Key DRM achievements,Policy enablers
B3: Legal and Institutional DRM Framework | C3: DRM policies and institutions | D3: =IF('DRM Diagnostic'!E14="Yes",1,0) -> 0 | E3: =IF('DRM Diagnostic'!G14="Yes",1,0) -> 0 | F3: =0.5*IF('DRM Diagnostic'!I14="Yes",1,0) + 0.5*IF('DRM Diagnostic'!I16="Yes",1,0) -> 0 | G3: =ROUND(0.3333*IF('DRM Diagnostic'!K14="Yes",1,0) + 0.3333*IF('DRM Diagnostic'!K15="Yes",1,0) + 0.3333*IF('DRM Diagnostic'!K16="Yes",1,0),2) -> 0 | I3: =_xlfn.TEXTJOIN(",",FALSE,B3:G3) -> Legal and Institutional DRM Framework,DRM policies and institutions,0,0,0,0
B4: Legal and Institutional DRM Framework | C4: Mainstreaming DRM into national and sectoral development plans | D4: =IF('DRM Diagnostic'!E19="Yes",1,0) -> 0 | E4: =IF('DRM Diagnostic'!G19="Yes",1,0) -> 0 | F4: =IF('DRM Diagnostic'!I19="Yes",1,0) -> 0 | G4: =IF('DRM Diagnostic'!K19="Yes",1,0) -> 0 | I4: =_xlfn.TEXTJOIN(",",FALSE,B4:G4) -> Legal and Institutional DRM Framework,Mainstreaming DRM into national and sectoral development plans,0,0,0,0
B5: Risk Identification | C5: Risk identification | D5: =IF('DRM Diagnostic'!E21="Yes",1,0) -> 0 | E5: =0.5*IF('DRM Diagnostic'!G21="Yes",1,0) + 0.5*IF('DRM Diagnostic'!G22="Yes",1,0) -> 0 | F5: =IF('DRM Diagnostic'!I21="Yes",1,0) -> 0 | G5: =IF('DRM Diagnostic'!K21="Yes",1,0) -> 0 | I5: =_xlfn.TEXTJOIN(",",FALSE,B5:G5) -> Risk Identification,Risk identification,0,0,0,0
B6: Risk Reduction | C6: Territorial and urban planning | D6: =IF('DRM Diagnostic'!E24="Yes",1,0) -> 0 | E6: =IF('DRM Diagnostic'!G24="Yes",1,0) -> 0 | F6: =IF('DRM Diagnostic'!I24="Yes",1,0) -> 0 | G6: =0.5*IF('DRM Diagnostic'!K24="Yes",1,0) + 0.5*IF('DRM Diagnostic'!K25="Yes",1,0) -> 0.5 | I6: =_xlfn.TEXTJOIN(",",FALSE,B6:G6) -> Risk Reduction,Territorial and urban planning,0,0,0,0.5
B7: Risk Reduction | C7: Public investment at the central level | D7: =IF('DRM Diagnostic'!E27="Yes",1,0) -> 0 | E7: =IF('DRM Diagnostic'!G27="Yes",1,0) -> 0 | F7: =IF('DRM Diagnostic'!I27="Yes",1,0) -> 0 | G7: =0.5*IF('DRM Diagnostic'!K27="Yes",1,0) + 0.5*IF('DRM Diagnostic'!K28="Yes",1,0) -> 0 | I7: =_xlfn.TEXTJOIN(",",FALSE,B7:G7) -> Risk Reduction,Public investment at the central level,0,0,0,0
B8: Risk Reduction | C8: Sector-specific risk reduction measures | D8: =0.2*IF('DRM Diagnostic'!E30="Yes",1,0)+0.2*IF('DRM Diagnostic'!E31="Yes",1,0)+0.2*IF('DRM Diagnostic'!E32="Yes",1,0)+0.2*IF('DRM Diagnostic'!E33="Yes",1,0)+0.2*IF('DRM Diagnostic'!E35="Yes",1,0) -> 0 | E8: =0.5*IF('DRM Diagnostic'!G30="Yes",1,0)+0.5*IF('DRM Diagnostic'!G35="Yes",1,0) -> 0 | F8: =ROUND(0.3333*IF('DRM Diagnostic'!I30="Yes",1,0)+0.3333*IF('DRM Diagnostic'!I35="Yes",1,0)+0.3333*IF('DRM Diagnostic'!I36="Yes",1,0),2) -> 0 | G8: =0.5*IF('DRM Diagnostic'!K30="Yes",1,0)+0.5*IF('DRM Diagnostic'!K35="Yes",1,0) -> 0 | I8: =_xlfn.TEXTJOIN(",",FALSE,B8:G8) -> Risk Reduction,Sector-specific risk reduction measures,0,0,0,0
B9: Preparedness | C9: Early warning systems | D9: =IF('DRM Diagnostic'!E38="Yes",1,0) -> 0 | E9: =IF('DRM Diagnostic'!G38="Yes",1,0) -> 0 | F9: =IF('DRM Diagnostic'!I38="Yes",1,0) -> 0 | G9: =IF('DRM Diagnostic'!K38="Yes",1,0) -> 0 | I9: =_xlfn.TEXTJOIN(",",FALSE,B9:G9) -> Preparedness,Early warning systems,0,0,0,0
B10: Preparedness | C10: Emergency preparedness and response | D10: =IF('DRM Diagnostic'!E40="Yes",1,0) -> 0 | E10: =IF('DRM Diagnostic'!G40="Yes",1,0) -> 0 | F10: =0.5*IF('DRM Diagnostic'!I40="Yes",1,0) + 0.5*IF('DRM Diagnostic'!I41="Yes",1,0) -> 0 | G10: =IF('DRM Diagnostic'!K40="Yes",1,0) -> 0 | I10: =_xlfn.TEXTJOIN(",",FALSE,B10:G10) -> Preparedness,Emergency preparedness and response,0,0,0,0
B11: Preparedness | C11: Adaptive social protection | D11: =IF('DRM Diagnostic'!E43="Yes",1,0) -> 0 | E11: =IF('DRM Diagnostic'!G43="Yes",1,0) -> 0 | F11: =IF('DRM Diagnostic'!I43="Yes",1,0) -> 0 | G11: =IF('DRM Diagnostic'!K43="Yes",1,0) -> 0 | I11: =_xlfn.TEXTJOIN(",",FALSE,B11:G11) -> Preparedness,Adaptive social protection,0,0,0,0
B12: Financial Protection | C12: Fiscal risk management | D12: =IF('DRM Diagnostic'!E45="Yes",1,0) -> 0 | E12: =IF('DRM Diagnostic'!G45="Yes",1,0) -> 0 | F12: =IF('DRM Diagnostic'!I45="Yes",1,0) -> 0 | G12: =IF('DRM Diagnostic'!K45="Yes",1,0) -> 0 | I12: =_xlfn.TEXTJOIN(",",FALSE,B12:G12) -> Financial Protection,Fiscal risk management,0,0,0,0
B13: Financial Protection | C13: DRF strategies and instruments | D13: =IF('DRM Diagnostic'!E47="Yes",1,0) -> 0 | E13: =0.5*IF('DRM Diagnostic'!G47="Yes",1,0)+0.5*IF('DRM Diagnostic'!G48="Yes",1,0) -> 0 | F13: =IF('DRM Diagnostic'!I47="Yes",1,0) -> 0 | G13: =IF('DRM Diagnostic'!K47="Yes",1,0) -> 0 | I13: =_xlfn.TEXTJOIN(",",FALSE,B13:G13) -> Financial Protection,DRF strategies and instruments,0,0,0,0
B14: Resilient Reconstruction | C14: Resilient reconstruction | D14: =IF('DRM Diagnostic'!E50="Yes",1,0) -> 0 | E14: =IF('DRM Diagnostic'!G50="Yes",1,0) -> 0 | F14: =IF('DRM Diagnostic'!I50="Yes",1,0) -> 0 | G14: =IF('DRM Diagnostic'!K50="Yes",1,0) -> 0 | I14: =_xlfn.TEXTJOIN(",",FALSE,B14:G14) -> Resilient Reconstruction,Resilient reconstruction,0,0,0,0
B46: sheet password is 1234
